upyter notebook --ip=0.0.0.0 --port=3000 --allow-root --NotebookApp.token='' --NotebookApp.password=''
Traceback (most recent call last):
  File "/nix/store/y7rl3157y28808sssnqyapwzb18fxz52-python3.11-notebook-7.2.0/bin/.jupyter-notebook-wrapped", line 6, in <module>
    from notebook.app import main
  File "/nix/store/avfsxapn2d1a7s741ybqwm03ldwcx92q-python3.12-notebook-7.2.0/lib/python3.12/site-packages/notebook/app.py", line 9, in <module>
    from jupyter_client.utils import ensure_async  # type:ignore[attr-defined]
    ^^^^^^^^^^^^^^^^^^^^^^^^^^^^^^^^^^^^^^^^^^^^^
  File "/nix/store/p57x4bfmfh1dwx9jxb6ldk04vjx9p75p-python3.12-jupyter-client-8.6.1/lib/python3.12/site-packages/jupyter_client/__init__.py", line 3, in <module>
    from .asynchronous import AsyncKernelClient
  File "/nix/store/p57x4bfmfh1dwx9jxb6ldk04vjx9p75p-python3.12-jupyter-client-8.6.1/lib/python3.12/site-packages/jupyter_client/asynchronous/__init__.py", line 1, in <module>
    from .client import AsyncKernelClient  # noqa
    ^^^^^^^^^^^^^^^^^^^^^^^^^^^^^^^^^^^^^
  File "/nix/store/p57x4bfmfh1dwx9jxb6ldk04vjx9p75p-python3.12-jupyter-client-8.6.1/lib/python3.12/site-packages/jupyter_client/asynchronous/client.py", line 8, in <module>
    import zmq.asyncio
  File "/nix/store/zf644z4jsr10srdy6r43w0azvnyys8dh-python3.12-pyzmq-25.1.2/lib/python3.12/site-packages/zmq/__init__.py", line 103, in <module>
    from zmq import backend
  File "/nix/store/zf644z4jsr10srdy6r43w0azvnyys8dh-python3.12-pyzmq-25.1.2/lib/python3.12/site-packages/zmq/backend/__init__.py", line 31, in <module>
    raise original_error from None
  File "/nix/store/zf644z4jsr10srdy6r43w0azvnyys8dh-python3.12-pyzmq-25.1.2/lib/python3.12/site-packages/zmq/backend/__init__.py", line 26, in <module>
    _ns = select_backend(first)
          ^^^^^^^^^^^^^^^^^^^^^
  File "/nix/store/zf644z4jsr10srdy6r43w0azvnyys8dh-python3.12-pyzmq-25.1.2/lib/python3.12/site-packages/zmq/backend/select.py", line 31, in select_backend
    mod = import_module(name)
          ^^^^^^^^^^^^^^^^^^^
  File "/nix/store/7hnr99nxrd2aw6lghybqdmkckq60j6l9-python3-3.11.9/lib/python3.11/importlib/__init__.py", line 126, in import_module
    return _bootstrap._gcd_import(name[level:], package, level)
           ^^^^^^^^^^^^^^^^^^^^^^^^^^^^^^^^^^^^^^^^^^^^^^^^^^^^
  File "/nix/store/zf644z4jsr10srdy6r43w0azvnyys8dh-python3.12-pyzmq-25.1.2/lib/python3.12/site-packages/zmq/backend/cython/__init__.py", line 6, in <module>
    from . import (
ImportError: cannot import name '_device' from partially initialized module 'zmq.backend.cython' (most likely due to a circular import) (/nix/store/zf644z4jsr10srdy6r43w0azvnyys8dh-python3.12-pyzmq-25.1.2/lib/python3.12/site-packages/zmq/backend/cython/__init__.py)